<?xml version="1.0" encoding="utf-8"?>
<!-- This URDF was automatically created by SolidWorks to URDF Exporter! Originally created by Stephen Brawner (brawner@gmail.com) 
     Commit Version: 1.6.0-4-g7f85cfe  Build Version: 1.6.7995.38578
     For more information, please see http://wiki.ros.org/sw_urdf_exporter -->
<robot
  name="arm_description">
  <link
    name="base_link">
    <inertial>
      <origin
        xyz="-0.119455 0.316401 -0.00859"
        rpy="0 0 0" />
      <mass
        value="0.079" />
      <inertia
        ixx="0.007931558"
        ixy="-0.002989401"
        ixz="7.4944E-05"
        iyy="0.001208874"
        iyz="-0.000222262"
        izz="0.009035413" />
    </inertial>
    <visual>
      <origin
        xyz="0 0 0"
        rpy="0 0 0" />
      <geometry>
        <mesh
          filename="package://arm_description/meshes/base_link.STL" />
      </geometry>
      <material
        name="">
        <color
          rgba="1 1 1 1" />
      </material>
    </visual>
    <collision>
      <origin
        xyz="0 0 0"
        rpy="0 0 0" />
      <geometry>
        <mesh
          filename="package://arm_description/meshes/base_link.STL" />
      </geometry>
    </collision>
  </link>
  <link
    name="link_1">
    <inertial>
      <origin
        xyz="0.0 0.0 0.018957"
        rpy="0 0 0" />
      <mass
        value="0.743" />
      <inertia
        ixx="0.056991104"
        ixy="-0.029729557"
        ixz="0.002091529"
        iyy="0.016721572"
        iyz="-0.003827803"
        izz="0.072694188" />
    </inertial>
    <visual>
      <origin
        xyz="0 0 0"
        rpy="0 0 0" />
      <geometry>
        <mesh
          filename="package://arm_description/meshes/Link1.STL" />
      </geometry>
      <material
        name="">
        <color
          rgba="0.79216 0.81961 0.93333 1" />
      </material>
    </visual>
    <collision>
      <origin
        xyz="0 0 0"
        rpy="0 0 0" />
      <geometry>
        <mesh
          filename="package://arm_description/meshes/Link1.STL" />
      </geometry>
    </collision>
  </link>
  <joint
    name="joint_1"
    type="revolute">
    <origin
      xyz="0 0 0.0465"
      rpy="0 0 0" />
    <parent
      link="base_link" />
    <child
      link="link_1" />
    <axis
      xyz="0 0 1" />
    <limit
      lower="-3.1"
      upper="3.1"
      effort="25"
      velocity="7.75" />
    <dynamics
      friction="0.2" />
  </joint>
  <link
    name="link_2">
    <inertial>
      <origin
        xyz="-0.0 0.150854 -0.0"
        rpy="0 0 0" />
      <mass
        value="0.106" />
      <inertia
        ixx="0.007704444"
        ixy="-0.011576301"
        ixz="0.005409182"
        iyy="0.025699817"
        iyz="-0.002350387"
        izz="0.030490625" />
    </inertial>
    <visual>
      <origin
        xyz="0 0 0"
        rpy="0 0 0" />
      <geometry>
        <mesh
          filename="package://arm_description/meshes/Link2.STL" />
      </geometry>
      <material
        name="">
        <color
          rgba="0.79216 0.81961 0.93333 1" />
      </material>
    </visual>
    <collision>
      <origin
        xyz="0 0 0"
        rpy="0 0 0" />
      <geometry>
        <mesh
          filename="package://arm_description/meshes/Link2.STL" />
      </geometry>
    </collision>
  </link>
  <joint
    name="joint_2"
    type="revolute">
    <origin
      xyz="0 0 0.0354"
      rpy="1.5708 0 3.1416" />
    <parent
      link="link_1" />
    <child
      link="link_2" />
    <axis
      xyz="0 0 -1" />
    <limit
      lower="-1.084"
      upper="1.426"
      effort="63"
      velocity="4.71" />
    <dynamics
      friction="0.2" />
  </joint>
  <link
    name="link_3">
    <inertial>
      <origin
        xyz="0.0201228 0.078046 0.00"
        rpy="0 0 0" />
      <mass
        value="0.257" />
      <inertia
        ixx="0.0017669"
        ixy="-0.002445484"
        ixz="0.002826134"
        iyy="0.009426086"
        iyz="-0.000831974"
        izz="0.009209849" />
    </inertial>
    <visual>
      <origin
        xyz="0 0 0"
        rpy="0 0 0" />
      <geometry>
        <mesh
          filename="package://arm_description/meshes/Link3.STL" />
      </geometry>
      <material
        name="">
        <color
          rgba="1 1 1 1" />
      </material>
    </visual>
    <collision>
      <origin
        xyz="0 0 0"
        rpy="0 0 0" />
      <geometry>
        <mesh
          filename="package://arm_description/meshes/Link3.STL" />
      </geometry>
    </collision>
  </link>
  <joint
    name="joint_3"
    type="revolute">
    <origin
      xyz="0 0.17331 0"
      rpy="0 0 1.5708" />
    <parent
      link="link_2" />
    <child
      link="link_3" />
    <axis
      xyz="0 0 -1" />
    <limit
      lower="-1.36217"
      upper="0.5335"
      effort="35"
      velocity="4.71" />
    <dynamics
      friction="0.2" />
  </joint>
  <link
    name="link_4">
    <inertial>
      <origin
        xyz="0.00097671 0.00017048 0.0840386"
        rpy="0 0 0" />
      <mass
        value="0.701" />
      <inertia
        ixx="0.000920659"
        ixy="0.000538358"
        ixz="0.001481875"
        iyy="0.004406711"
        iyz="0.000240297"
        izz="0.003960406" />
    </inertial>
    <visual>
      <origin
        xyz="0 0 0"
        rpy="0 0 0" />
      <geometry>
        <mesh
          filename="package://arm_description/meshes/Link4.STL" />
      </geometry>
      <material
        name="">
        <color
          rgba="1 1 1 1" />
      </material>
    </visual>
    <collision>
      <origin
        xyz="0 0 0"
        rpy="0 0 0" />
      <geometry>
        <mesh
          filename="package://arm_description/meshes/Link4.STL" />
      </geometry>
    </collision>
  </link>
  <joint
    name="joint_4"
    type="revolute">
    <origin
      xyz="0.019039 0.092852 -0.01035"
      rpy="-1.5708 0 0" />
    <parent
      link="link_3" />
    <child
      link="link_4" />
    <axis
      xyz="0 0 1" />
    <limit
      lower="-3.14"
      upper="3.14"
      effort="18"
      velocity="7.54" />
    <dynamics
      friction="0.2" />
  </joint>
  <link
    name="link_5">
    <inertial>
      <origin
        xyz="0.00046899 0.0353957 -0.0024708"
        rpy="0 0 0" />
      <mass
        value="0.200" />
      <inertia
        ixx="0.000542273"
        ixy="0.000339371"
        ixz="0.000139679"
        iyy="0.000462047"
        iyz="0.000192007"
        izz="0.000768102" />
    </inertial>
    <visual>
      <origin
        xyz="0 0 0"
        rpy="0 0 0" />
      <geometry>
        <mesh
          filename="package://arm_description/meshes/Link5.STL" />
      </geometry>
      <material
        name="">
        <color
          rgba="1 1 1 1" />
      </material>
    </visual>
    <collision>
      <origin
        xyz="0 0 0"
        rpy="0 0 0" />
      <geometry>
        <mesh
          filename="package://arm_description/meshes/Link5.STL" />
      </geometry>
    </collision>
  </link>
  <joint
    name="joint_5"
    type="revolute">
    <origin
      xyz="0 0 0.11484"
      rpy="1.5708 0 0" />
    <parent
      link="link_4" />
    <child
      link="link_5" />
    <axis
      xyz="0 0 -1" />
    <limit
      lower="-1.74"
      upper="1.74"
      effort="6"
      velocity="24.61" />
    <dynamics
      friction="0.2" />
  </joint>
  <link
    name="link_6">
    <inertial>
      <origin
        xyz="0.0 0.0 -0.11807"
        rpy="0 0 0" />
      <mass
        value="0.600" />
      <inertia
        ixx="0.002122325"
        ixy="-0.00024356"
        ixz="-1.4388E-05"
        iyy="0.000245908"
        iyz="0.000209453"
        izz="0.002149884" />
    </inertial>
    <visual>
      <origin
        xyz="0 0 0"
        rpy="0 0 0" />
      <geometry>
        <mesh
          filename="package://arm_description/meshes/Link6.STL" />
      </geometry>
      <material
        name="">
        <color
          rgba="0.75294 0.75294 0.75294 1" />
      </material>
    </visual>
    <collision>
      <origin
        xyz="0 0 0"
        rpy="0 0 0" />
      <geometry>
        <mesh
          filename="package://arm_description/meshes/Link6.STL" />
      </geometry>
    </collision>
  </link>
  <joint
    name="joint_6"
    type="revolute">
    <origin
      xyz="0 0.0739 0"
      rpy="1.5708 0 0" />
    <parent
      link="link_5" />
    <child
      link="link_6" />
    <axis
      xyz="0 0 1" />
    <limit
      lower="-3.14"
      upper="3.14"
      effort="3"
      velocity="10" />
    <dynamics
      friction="0.2" />
  </joint>
</robot>