<?xml version="1.0" encoding="utf-8"?>
<!-- This URDF was automatically created by SolidWorks to URDF Exporter! Originally created by Stephen Brawner (brawner@gmail.com) 
     Commit Version: 1.6.0-4-g7f85cfe  Build Version: 1.6.7995.38578
     For more information, please see http://wiki.ros.org/sw_urdf_exporter -->
<robot
  name="arm_description">
  <link
    name="base_link">
    <inertial>
      <origin
        xyz="1.32154299112504E-18 7.7782856302198E-18 0.00599999999999999"
        rpy="0 0 0" />
      <mass
        value="0.402123859659494" />
      <inertia
        ixx="0.0017915958360696"
        ixy="2.15436653852225E-19"
        ixz="3.77444977383238E-19"
        iyy="0.0017915958360696"
        iyz="6.59832203544841E-19"
        izz="0.0035789023509695" />
    </inertial>
    <visual>
      <origin
        xyz="0 0 0"
        rpy="0 0 0" />
      <geometry>
        <mesh
          filename="package://arm_description/meshes/base_link.STL" />
      </geometry>
      <material
        name="">
        <color
          rgba="1 1 1 1" />
      </material>
    </visual>
    <collision>
      <origin
        xyz="0 0 0"
        rpy="0 0 0" />
      <geometry>
        <mesh
          filename="package://arm_description/meshes/base_link.STL" />
      </geometry>
    </collision>
  </link>
  <link
    name="link_1">
    <inertial>
      <origin
        xyz="-0.008872 -0.0076588 0.05919"
        rpy="0 0 0" />
      <mass
        value="0.25868" />
      <inertia
        ixx="0.00010631"
        ixy="4.1029E-07"
        ixz="6.453E-08"
        iyy="0.00019756"
        iyz="8.1039E-07"
        izz="0.00012615" />
    </inertial>
    <visual>
      <origin
        xyz="0 0 0"
        rpy="0 0 0" />
      <geometry>
        <mesh
          filename="package://arm_description/meshes/link_1.STL" />
      </geometry>
      <material
        name="">
        <color
          rgba="0.75294 0.75294 0.75294 1" />
      </material>
    </visual>
    <collision>
      <origin
        xyz="0 0 0"
        rpy="0 0 0" />
      <geometry>
        <mesh
          filename="package://arm_description/meshes/link_1.STL" />
      </geometry>
    </collision>
  </link>
  <joint
    name="joint_1"
    type="revolute">
    <origin
      xyz="0 0 0"
      rpy="0 0 0" />
    <parent
      link="base_link" />
    <child
      link="link_1" />
    <axis
      xyz="0 0 1" />
    <limit
      lower="-3"
      upper="3"
      effort="30"
      velocity="5" />
    <dynamics
      friction="0.3" />
  </joint>
  <link
    name="link_2">
    <inertial>
      <origin
        xyz="-5.5408E-05 0.20382 0.0196"
        rpy="0 0 0" />
      <mass
        value="0.18736" />
      <inertia
        ixx="0.0011226"
        ixy="3.319E-08"
        ixz="8.6801E-09"
        iyy="6.675E-05"
        iyz="1.0385E-06"
        izz="0.001153" />
    </inertial>
    <visual>
      <origin
        xyz="0 0 0"
        rpy="0 0 0" />
      <geometry>
        <mesh
          filename="package://arm_description/meshes/link_2.STL" />
      </geometry>
      <material
        name="">
        <color
          rgba="0.75294 0.75294 0.75294 1" />
      </material>
    </visual>
    <collision>
      <origin
        xyz="0 0 0"
        rpy="0 0 0" />
      <geometry>
        <mesh
          filename="package://arm_description/meshes/link_2.STL" />
      </geometry>
    </collision>
  </link>
  <joint
    name="joint_2"
    type="revolute">
    <origin
      xyz="0 -0.042 0.071"
      rpy="1.5708 0 0" />
    <parent
      link="link_1" />
    <child
      link="link_2" />
    <axis
      xyz="0 0 1" />
    <limit
      lower="-1.5"
      upper="1.5"
      effort="35"
      velocity="5" />
    <dynamics
      friction="0.2" />
  </joint>
  <link
    name="link_3">
    <inertial>
      <origin
        xyz="0.015906 -0.043689 -0.029685"
        rpy="0 0 0" />
      <mass
        value="0.42456" />
      <inertia
        ixx="0.00024338"
        ixy="1.4136E-05"
        ixz="4.2117E-07"
        iyy="0.00016451"
        iyz="-9.8124E-07"
        izz="0.00030978" />
    </inertial>
    <visual>
      <origin
        xyz="0 0 0"
        rpy="0 0 0" />
      <geometry>
        <mesh
          filename="package://arm_description/meshes/link_3.STL" />
      </geometry>
      <material
        name="">
        <color
          rgba="0.75294 0.75294 0.75294 1" />
      </material>
    </visual>
    <collision>
      <origin
        xyz="0 0 0"
        rpy="0 0 0" />
      <geometry>
        <mesh
          filename="package://arm_description/meshes/link_3.STL" />
      </geometry>
    </collision>
  </link>
  <joint
    name="joint_3"
    type="revolute">
    <origin
      xyz="0 0.37 -0.007"
      rpy="0 0 1.5708" />
    <parent
      link="link_2" />
    <child
      link="link_3" />
    <axis
      xyz="0 0 1" />
    <limit
      lower="-0.8"
      upper="0.5"
      effort="35"
      velocity="5" />
    <dynamics
      friction="0.2" />
  </joint>
  <link
    name="link_4">
    <inertial>
      <origin
        xyz="0.00079034 0.0018966 0.16189"
        rpy="0 0 0" />
      <mass
        value="0.25332" />
      <inertia
        ixx="0.00019016"
        ixy="-1.4559E-08"
        ixz="1.0519E-06"
        iyy="0.00021072"
        iyz="-8.1559E-07"
        izz="6.0156E-05" />
    </inertial>
    <visual>
      <origin
        xyz="0 0 0"
        rpy="0 0 0" />
      <geometry>
        <mesh
          filename="package://arm_description/meshes/link_4.STL" />
      </geometry>
      <material
        name="">
        <color
          rgba="0.75294 0.75294 0.75294 1" />
      </material>
    </visual>
    <collision>
      <origin
        xyz="0 0 0"
        rpy="0 0 0" />
      <geometry>
        <mesh
          filename="package://arm_description/meshes/link_4.STL" />
      </geometry>
    </collision>
  </link>
  <joint
    name="joint_4"
    type="revolute">
    <origin
      xyz="0.03 -0.1419 -0.035"
      rpy="1.5708 0 0" />
    <parent
      link="link_3" />
    <child
      link="link_4" />
    <axis
      xyz="0 0 1" />
    <limit
      lower="-3.14"
      upper="3.14"
      effort="20"
      velocity="5" />
    <dynamics
      friction="0.2" />
  </joint>
  <link
    name="link_5">
    <inertial>
      <origin
        xyz="7.8329E-07 0.009346 -0.00086416"
        rpy="0 0 0" />
      <mass
        value="0.080964" />
      <inertia
        ixx="2.1219E-05"
        ixy="-6.2766E-10"
        ixz="-1.0499E-09"
        iyy="2.8653E-05"
        iyz="-6.0183E-08"
        izz="1.9054E-05" />
    </inertial>
    <visual>
      <origin
        xyz="0 0 0"
        rpy="0 0 0" />
      <geometry>
        <mesh
          filename="package://arm_description/meshes/link_5.STL" />
      </geometry>
      <material
        name="">
        <color
          rgba="0.75294 0.75294 0.75294 1" />
      </material>
    </visual>
    <collision>
      <origin
        xyz="0 0 0"
        rpy="0 0 0" />
      <geometry>
        <mesh
          filename="package://arm_description/meshes/link_5.STL" />
      </geometry>
    </collision>
  </link>
  <joint
    name="joint_5"
    type="revolute">
    <origin
      xyz="0 0 0.2591"
      rpy="1.5708 0 0" />
    <parent
      link="link_4" />
    <child
      link="link_5" />
    <axis
      xyz="0 0 -1" />
    <limit
      lower="-1.3"
      upper="1.3"
      effort="10"
      velocity="5" />
    <dynamics
      friction="0.2" />
  </joint>
  <link
    name="link_6">
    <inertial>
      <origin
        xyz="-5.5511E-17 -7.961E-21 -0.0084425"
        rpy="0 0 0" />
      <mass
        value="0.011935" />
      <inertia
        ixx="9.5493E-07"
        ixy="-4.6557E-25"
        ixz="-1.44E-24"
        iyy="9.5493E-07"
        iyz="5.6455E-25"
        izz="1.3427E-06" />
    </inertial>
    <visual>
      <origin
        xyz="0 0 0"
        rpy="0 0 0" />
      <geometry>
        <mesh
          filename="package://arm_description/meshes/link_6.STL" />
      </geometry>
      <material
        name="">
        <color
          rgba="1 1 1 1" />
      </material>
    </visual>
    <collision>
      <origin
        xyz="0 0 0"
        rpy="0 0 0" />
      <geometry>
        <mesh
          filename="package://arm_description/meshes/link_6.STL" />
      </geometry>
    </collision>
  </link>
  <joint
    name="joint_6"
    type="revolute">
    <origin
      xyz="0 0.026 0"
      rpy="1.5708 0 0" />
    <parent
      link="link_5" />
    <child
      link="link_6" />
    <axis
      xyz="0 0 1" />
    <limit
      lower="-2.9"
      upper="2.9"
      effort="4"
      velocity="5" />
    <dynamics
      friction="0.2" />
  </joint>
</robot>